2024-09-19 16:34:04,059: - discord.client - WARNING - PyNaCl is not installed, voice will NOT be supported
2024-09-19 16:34:04,327: - discord.client - INFO - logging in using static token
2024-09-19 16:34:05,537: - discord.gateway - INFO - Shard ID 0 has connected to Gateway (Session ID: 58807fa2e44d5835944d466b838bae35).
2024-09-19 16:34:07,556: - discord.client - ERROR - Ignoring exception in on_ready
Traceback (most recent call last):
  File "F:\Projetos\Yume²\.venv\Lib\site-packages\discord\client.py", line 441, in _run_event
    await coro(*args, **kwargs)
  File "F:\Projetos\Yume²\yume.py", line 48, in on_ready
    yume_status.start()
  File "F:\Projetos\Yume²\.venv\Lib\site-packages\discord\ext\tasks\__init__.py", line 392, in start
    raise RuntimeError('Task is already launched and is not completed.')
RuntimeError: Task is already launched and is not completed.
2024-09-19 16:34:20,250: - discord.client - WARNING - PyNaCl is not installed, voice will NOT be supported
2024-09-19 16:34:20,523: - discord.client - INFO - logging in using static token
2024-09-19 16:34:21,675: - discord.gateway - INFO - Shard ID 0 has connected to Gateway (Session ID: 98c76e8dc0c2ee147ca1f3df92a9d2fa).
2024-09-19 16:34:23,692: - discord.client - ERROR - Ignoring exception in on_ready
Traceback (most recent call last):
  File "F:\Projetos\Yume²\.venv\Lib\site-packages\discord\client.py", line 441, in _run_event
    await coro(*args, **kwargs)
  File "F:\Projetos\Yume²\yume.py", line 48, in on_ready
    yume_status.start()
  File "F:\Projetos\Yume²\.venv\Lib\site-packages\discord\ext\tasks\__init__.py", line 392, in start
    raise RuntimeError('Task is already launched and is not completed.')
RuntimeError: Task is already launched and is not completed.
2024-09-19 16:37:50,023: - discord.client - WARNING - PyNaCl is not installed, voice will NOT be supported
2024-09-19 16:37:50,289: - discord.client - INFO - logging in using static token
2024-09-19 16:37:51,710: - discord.gateway - INFO - Shard ID 0 has connected to Gateway (Session ID: d12937e70f2b35a840a6b32a75c91e89).
2024-09-19 16:37:53,719: - discord.client - ERROR - Ignoring exception in on_ready
Traceback (most recent call last):
  File "F:\Projetos\Yume²\.venv\Lib\site-packages\discord\client.py", line 441, in _run_event
    await coro(*args, **kwargs)
  File "F:\Projetos\Yume²\yume.py", line 48, in on_ready
    yume_status.start()
  File "F:\Projetos\Yume²\.venv\Lib\site-packages\discord\ext\tasks\__init__.py", line 392, in start
    raise RuntimeError('Task is already launched and is not completed.')
RuntimeError: Task is already launched and is not completed.
2024-09-19 16:38:54,028: - discord.client - WARNING - PyNaCl is not installed, voice will NOT be supported
2024-09-19 16:38:54,288: - discord.client - INFO - logging in using static token
2024-09-19 16:38:55,347: - discord.gateway - INFO - Shard ID 0 has connected to Gateway (Session ID: dd33de551c7d3d838119de7b5384377e).
2024-09-19 16:38:57,384: - discord.client - ERROR - Ignoring exception in on_ready
Traceback (most recent call last):
  File "F:\Projetos\Yume²\.venv\Lib\site-packages\discord\client.py", line 441, in _run_event
    await coro(*args, **kwargs)
  File "F:\Projetos\Yume²\yume.py", line 48, in on_ready
    yume_status.start()
  File "F:\Projetos\Yume²\.venv\Lib\site-packages\discord\ext\tasks\__init__.py", line 392, in start
    raise RuntimeError('Task is already launched and is not completed.')
RuntimeError: Task is already launched and is not completed.
2024-09-19 16:47:23,865: - discord.client - WARNING - PyNaCl is not installed, voice will NOT be supported
2024-09-19 16:47:24,151: - discord.client - INFO - logging in using static token
2024-09-19 16:47:25,549: - discord.gateway - INFO - Shard ID 0 has connected to Gateway (Session ID: 092410c0c11f0f3ce108e502f93f0fba).
2024-09-19 16:47:27,593: - discord.client - ERROR - Ignoring exception in on_ready
Traceback (most recent call last):
  File "F:\Projetos\Yume²\.venv\Lib\site-packages\discord\client.py", line 441, in _run_event
    await coro(*args, **kwargs)
  File "F:\Projetos\Yume²\yume.py", line 48, in on_ready
    yume_status.start()
  File "F:\Projetos\Yume²\.venv\Lib\site-packages\discord\ext\tasks\__init__.py", line 392, in start
    raise RuntimeError('Task is already launched and is not completed.')
RuntimeError: Task is already launched and is not completed.
2024-09-19 16:48:07,122: - discord.client - WARNING - PyNaCl is not installed, voice will NOT be supported
2024-09-19 16:48:07,402: - discord.client - INFO - logging in using static token
2024-09-19 16:48:08,614: - discord.gateway - INFO - Shard ID 0 has connected to Gateway (Session ID: be54e6882e903b4d4311c81fa0954e67).
2024-09-19 16:48:10,728: - discord.client - ERROR - Ignoring exception in on_ready
Traceback (most recent call last):
  File "F:\Projetos\Yume²\.venv\Lib\site-packages\discord\client.py", line 441, in _run_event
    await coro(*args, **kwargs)
  File "F:\Projetos\Yume²\yume.py", line 48, in on_ready
    yume_status.start()
  File "F:\Projetos\Yume²\.venv\Lib\site-packages\discord\ext\tasks\__init__.py", line 392, in start
    raise RuntimeError('Task is already launched and is not completed.')
RuntimeError: Task is already launched and is not completed.
2024-09-19 16:49:06,766: - discord.client - WARNING - PyNaCl is not installed, voice will NOT be supported
2024-09-19 16:49:07,068: - discord.client - INFO - logging in using static token
2024-09-19 16:49:08,317: - discord.gateway - INFO - Shard ID 0 has connected to Gateway (Session ID: 79b7c7a2910c138e2724e15b120a419e).
2024-09-19 16:49:10,345: - discord.client - ERROR - Ignoring exception in on_ready
Traceback (most recent call last):
  File "F:\Projetos\Yume²\.venv\Lib\site-packages\discord\client.py", line 441, in _run_event
    await coro(*args, **kwargs)
  File "F:\Projetos\Yume²\yume.py", line 48, in on_ready
    yume_status.start()
  File "F:\Projetos\Yume²\.venv\Lib\site-packages\discord\ext\tasks\__init__.py", line 392, in start
    raise RuntimeError('Task is already launched and is not completed.')
RuntimeError: Task is already launched and is not completed.
2024-09-19 19:48:10,259: - discord.client - WARNING - PyNaCl is not installed, voice will NOT be supported
2024-09-19 19:48:10,738: - discord.client - INFO - logging in using static token
2024-09-19 19:48:11,879: - discord.gateway - INFO - Shard ID 0 has connected to Gateway (Session ID: 9041d367cb3417a815b72fe9e5b22a2b).
2024-09-19 19:48:13,930: - discord.client - ERROR - Ignoring exception in on_ready
Traceback (most recent call last):
  File "F:\Projetos\Yume²\.venv\Lib\site-packages\discord\client.py", line 441, in _run_event
    await coro(*args, **kwargs)
  File "F:\Projetos\Yume²\yume.py", line 48, in on_ready
    yume_status.start()
  File "F:\Projetos\Yume²\.venv\Lib\site-packages\discord\ext\tasks\__init__.py", line 392, in start
    raise RuntimeError('Task is already launched and is not completed.')
RuntimeError: Task is already launched and is not completed.
2024-09-19 19:48:21,934: - discord.app_commands.tree - ERROR - Ignoring exception in command 'smug'
Traceback (most recent call last):
  File "F:\Projetos\Yume²\.venv\Lib\site-packages\discord\app_commands\commands.py", line 827, in _do_call
    return await self._callback(self.binding, interaction, **params)  # type: ignore
           ^^^^^^^^^^^^^^^^^^^^^^^^^^^^^^^^^^^^^^^^^^^^^^^^^^^^^^^^^
  File "F:\Projetos\Yume²\cogs\actions.py", line 29, in smug
    await interaction.response.send_message(embed=embed, view=await buttons.ActionButtons.smug_button)
                                                              ^^^^^^^^^^^^^^^^^^^^^^^^^^^^^^^^^^^^^^^
TypeError: object function can't be used in 'await' expression

The above exception was the direct cause of the following exception:

Traceback (most recent call last):
  File "F:\Projetos\Yume²\.venv\Lib\site-packages\discord\app_commands\tree.py", line 1248, in _call
    await command._invoke_with_namespace(interaction, namespace)
  File "F:\Projetos\Yume²\.venv\Lib\site-packages\discord\app_commands\commands.py", line 853, in _invoke_with_namespace
    return await self._do_call(interaction, transformed_values)
           ^^^^^^^^^^^^^^^^^^^^^^^^^^^^^^^^^^^^^^^^^^^^^^^^^^^^
  File "F:\Projetos\Yume²\.venv\Lib\site-packages\discord\app_commands\commands.py", line 842, in _do_call
    raise CommandInvokeError(self, e) from e
discord.app_commands.errors.CommandInvokeError: Command 'smug' raised an exception: TypeError: object function can't be used in 'await' expression
2024-09-19 19:48:48,206: - discord.client - WARNING - PyNaCl is not installed, voice will NOT be supported
2024-09-19 19:48:48,434: - discord.client - INFO - logging in using static token
2024-09-19 19:48:49,635: - discord.gateway - INFO - Shard ID 0 has connected to Gateway (Session ID: 324cd0b165aea691d6db01130c5d47fa).
2024-09-19 19:48:51,652: - discord.client - ERROR - Ignoring exception in on_ready
Traceback (most recent call last):
  File "F:\Projetos\Yume²\.venv\Lib\site-packages\discord\client.py", line 441, in _run_event
    await coro(*args, **kwargs)
  File "F:\Projetos\Yume²\yume.py", line 48, in on_ready
    yume_status.start()
  File "F:\Projetos\Yume²\.venv\Lib\site-packages\discord\ext\tasks\__init__.py", line 392, in start
    raise RuntimeError('Task is already launched and is not completed.')
RuntimeError: Task is already launched and is not completed.
2024-09-19 19:49:12,907: - discord.app_commands.tree - ERROR - Ignoring exception in command 'smug'
Traceback (most recent call last):
  File "F:\Projetos\Yume²\.venv\Lib\site-packages\discord\app_commands\commands.py", line 827, in _do_call
    return await self._callback(self.binding, interaction, **params)  # type: ignore
           ^^^^^^^^^^^^^^^^^^^^^^^^^^^^^^^^^^^^^^^^^^^^^^^^^^^^^^^^^
  File "F:\Projetos\Yume²\cogs\actions.py", line 29, in smug
    await interaction.response.send_message(embed=embed, view=buttons.ActionButtons.smug_button)
  File "F:\Projetos\Yume²\.venv\Lib\site-packages\discord\interactions.py", line 786, in send_message
    params = interaction_message_response_params(
             ^^^^^^^^^^^^^^^^^^^^^^^^^^^^^^^^^^^^
  File "F:\Projetos\Yume²\.venv\Lib\site-packages\discord\webhook\async_.py", line 578, in interaction_message_response_params
    data['components'] = view.to_components()
                         ^^^^^^^^^^^^^^^^^^
AttributeError: 'function' object has no attribute 'to_components'

The above exception was the direct cause of the following exception:

Traceback (most recent call last):
  File "F:\Projetos\Yume²\.venv\Lib\site-packages\discord\app_commands\tree.py", line 1248, in _call
    await command._invoke_with_namespace(interaction, namespace)
  File "F:\Projetos\Yume²\.venv\Lib\site-packages\discord\app_commands\commands.py", line 853, in _invoke_with_namespace
    return await self._do_call(interaction, transformed_values)
           ^^^^^^^^^^^^^^^^^^^^^^^^^^^^^^^^^^^^^^^^^^^^^^^^^^^^
  File "F:\Projetos\Yume²\.venv\Lib\site-packages\discord\app_commands\commands.py", line 846, in _do_call
    raise CommandInvokeError(self, e) from e
discord.app_commands.errors.CommandInvokeError: Command 'smug' raised an exception: AttributeError: 'function' object has no attribute 'to_components'
2024-09-19 19:50:13,000: - discord.client - WARNING - PyNaCl is not installed, voice will NOT be supported
2024-09-19 19:50:13,365: - discord.client - INFO - logging in using static token
2024-09-19 19:50:14,582: - discord.gateway - INFO - Shard ID 0 has connected to Gateway (Session ID: 4d67f6ba4e836518058eb96672161cdd).
2024-09-19 19:50:16,610: - discord.client - ERROR - Ignoring exception in on_ready
Traceback (most recent call last):
  File "F:\Projetos\Yume²\.venv\Lib\site-packages\discord\client.py", line 441, in _run_event
    await coro(*args, **kwargs)
  File "F:\Projetos\Yume²\yume.py", line 48, in on_ready
    yume_status.start()
  File "F:\Projetos\Yume²\.venv\Lib\site-packages\discord\ext\tasks\__init__.py", line 392, in start
    raise RuntimeError('Task is already launched and is not completed.')
RuntimeError: Task is already launched and is not completed.
2024-09-19 19:50:43,658: - discord.app_commands.tree - ERROR - Ignoring exception in command 'smug'
Traceback (most recent call last):
  File "F:\Projetos\Yume²\.venv\Lib\site-packages\discord\app_commands\commands.py", line 827, in _do_call
    return await self._callback(self.binding, interaction, **params)  # type: ignore
           ^^^^^^^^^^^^^^^^^^^^^^^^^^^^^^^^^^^^^^^^^^^^^^^^^^^^^^^^^
  File "F:\Projetos\Yume²\cogs\actions.py", line 30, in smug
    await interaction.response.send_message(embed=embed, view=view)
  File "F:\Projetos\Yume²\.venv\Lib\site-packages\discord\interactions.py", line 786, in send_message
    params = interaction_message_response_params(
             ^^^^^^^^^^^^^^^^^^^^^^^^^^^^^^^^^^^^
  File "F:\Projetos\Yume²\.venv\Lib\site-packages\discord\webhook\async_.py", line 578, in interaction_message_response_params
    data['components'] = view.to_components()
                         ^^^^^^^^^^^^^^^^^^
AttributeError: 'function' object has no attribute 'to_components'

The above exception was the direct cause of the following exception:

Traceback (most recent call last):
  File "F:\Projetos\Yume²\.venv\Lib\site-packages\discord\app_commands\tree.py", line 1248, in _call
    await command._invoke_with_namespace(interaction, namespace)
  File "F:\Projetos\Yume²\.venv\Lib\site-packages\discord\app_commands\commands.py", line 853, in _invoke_with_namespace
    return await self._do_call(interaction, transformed_values)
           ^^^^^^^^^^^^^^^^^^^^^^^^^^^^^^^^^^^^^^^^^^^^^^^^^^^^
  File "F:\Projetos\Yume²\.venv\Lib\site-packages\discord\app_commands\commands.py", line 846, in _do_call
    raise CommandInvokeError(self, e) from e
discord.app_commands.errors.CommandInvokeError: Command 'smug' raised an exception: AttributeError: 'function' object has no attribute 'to_components'
2024-09-19 19:51:00,028: - discord.client - WARNING - PyNaCl is not installed, voice will NOT be supported
2024-09-19 19:51:00,314: - discord.client - INFO - logging in using static token
2024-09-19 19:51:01,487: - discord.gateway - INFO - Shard ID 0 has connected to Gateway (Session ID: 4913b02c05bd2330cd89c3096d5da284).
2024-09-19 19:51:03,517: - discord.client - ERROR - Ignoring exception in on_ready
Traceback (most recent call last):
  File "F:\Projetos\Yume²\.venv\Lib\site-packages\discord\client.py", line 441, in _run_event
    await coro(*args, **kwargs)
  File "F:\Projetos\Yume²\yume.py", line 48, in on_ready
    yume_status.start()
  File "F:\Projetos\Yume²\.venv\Lib\site-packages\discord\ext\tasks\__init__.py", line 392, in start
    raise RuntimeError('Task is already launched and is not completed.')
RuntimeError: Task is already launched and is not completed.
2024-09-19 19:51:10,572: - discord.app_commands.tree - ERROR - Ignoring exception in command 'smug'
Traceback (most recent call last):
  File "F:\Projetos\Yume²\.venv\Lib\site-packages\discord\app_commands\commands.py", line 827, in _do_call
    return await self._callback(self.binding, interaction, **params)  # type: ignore
           ^^^^^^^^^^^^^^^^^^^^^^^^^^^^^^^^^^^^^^^^^^^^^^^^^^^^^^^^^
  File "F:\Projetos\Yume²\cogs\actions.py", line 29, in smug
    view = buttons.ActionButtons.smug_button()
           ^^^^^^^^^^^^^^^^^^^^^^^^^^^^^^^^^^^
TypeError: ActionButtons.smug_button() missing 3 required positional arguments: 'self', 'button', and 'interaction'

The above exception was the direct cause of the following exception:

Traceback (most recent call last):
  File "F:\Projetos\Yume²\.venv\Lib\site-packages\discord\app_commands\tree.py", line 1248, in _call
    await command._invoke_with_namespace(interaction, namespace)
  File "F:\Projetos\Yume²\.venv\Lib\site-packages\discord\app_commands\commands.py", line 853, in _invoke_with_namespace
    return await self._do_call(interaction, transformed_values)
           ^^^^^^^^^^^^^^^^^^^^^^^^^^^^^^^^^^^^^^^^^^^^^^^^^^^^
  File "F:\Projetos\Yume²\.venv\Lib\site-packages\discord\app_commands\commands.py", line 842, in _do_call
    raise CommandInvokeError(self, e) from e
discord.app_commands.errors.CommandInvokeError: Command 'smug' raised an exception: TypeError: ActionButtons.smug_button() missing 3 required positional arguments: 'self', 'button', and 'interaction'
2024-09-19 19:52:47,785: - discord.client - WARNING - PyNaCl is not installed, voice will NOT be supported
2024-09-19 19:52:48,046: - discord.client - INFO - logging in using static token
2024-09-19 19:52:49,276: - discord.gateway - INFO - Shard ID 0 has connected to Gateway (Session ID: 7d6bfe813d56770dd728f1a940c7db21).
2024-09-19 19:52:51,281: - discord.client - ERROR - Ignoring exception in on_ready
Traceback (most recent call last):
  File "F:\Projetos\Yume²\.venv\Lib\site-packages\discord\client.py", line 441, in _run_event
    await coro(*args, **kwargs)
  File "F:\Projetos\Yume²\yume.py", line 48, in on_ready
    yume_status.start()
  File "F:\Projetos\Yume²\.venv\Lib\site-packages\discord\ext\tasks\__init__.py", line 392, in start
    raise RuntimeError('Task is already launched and is not completed.')
RuntimeError: Task is already launched and is not completed.
2024-09-19 19:53:11,179: - discord.ui.view - ERROR - Ignoring exception in view <ActionButtons timeout=180.0 children=1> for item <Button style=<ButtonStyle.primary: 1> url=None disabled=False label='Smug Back' emoji=None row=None>
Traceback (most recent call last):
  File "F:\Projetos\Yume²\.venv\Lib\site-packages\discord\ui\view.py", line 427, in _scheduled_task
    await item.callback(interaction)
  File "F:\Projetos\Yume²\utils\buttons.py", line 13, in smug_button
    await interaction.response.send_message("uwu")
          ^^^^^^^^^^^^^^^^^^^^
AttributeError: 'Button' object has no attribute 'response'
2024-09-19 19:53:16,139: - discord.ui.view - ERROR - Ignoring exception in view <ActionButtons timeout=180.0 children=1> for item <Button style=<ButtonStyle.primary: 1> url=None disabled=False label='Smug Back' emoji=None row=None>
Traceback (most recent call last):
  File "F:\Projetos\Yume²\.venv\Lib\site-packages\discord\ui\view.py", line 427, in _scheduled_task
    await item.callback(interaction)
  File "F:\Projetos\Yume²\utils\buttons.py", line 13, in smug_button
    await interaction.response.send_message("uwu")
          ^^^^^^^^^^^^^^^^^^^^
AttributeError: 'Button' object has no attribute 'response'
2024-09-19 19:54:53,721: - discord.client - WARNING - PyNaCl is not installed, voice will NOT be supported
2024-09-19 19:54:53,730: - discord.client - INFO - logging in using static token
2024-09-19 19:54:54,900: - discord.gateway - INFO - Shard ID 0 has connected to Gateway (Session ID: 56c54bc4c7c2511bea8346db5b954d38).
2024-09-19 19:54:56,933: - discord.client - ERROR - Ignoring exception in on_ready
Traceback (most recent call last):
  File "F:\Projetos\Yume²\.venv\Lib\site-packages\discord\client.py", line 441, in _run_event
    await coro(*args, **kwargs)
  File "F:\Projetos\Yume²\yume.py", line 48, in on_ready
    yume_status.start()
  File "F:\Projetos\Yume²\.venv\Lib\site-packages\discord\ext\tasks\__init__.py", line 392, in start
    raise RuntimeError('Task is already launched and is not completed.')
RuntimeError: Task is already launched and is not completed.
2024-09-19 19:59:07,944: - discord.client - WARNING - PyNaCl is not installed, voice will NOT be supported
2024-09-19 19:59:07,953: - discord.client - INFO - logging in using static token
2024-09-19 19:59:09,163: - discord.gateway - INFO - Shard ID 0 has connected to Gateway (Session ID: 5d3125ca739d3bc5e66108d3510e09f9).
2024-09-19 19:59:11,189: - discord.client - ERROR - Ignoring exception in on_ready
Traceback (most recent call last):
  File "F:\Projetos\Yume²\.venv\Lib\site-packages\discord\client.py", line 441, in _run_event
    await coro(*args, **kwargs)
  File "F:\Projetos\Yume²\yume.py", line 47, in on_ready
    yume_status.start()
  File "F:\Projetos\Yume²\.venv\Lib\site-packages\discord\ext\tasks\__init__.py", line 392, in start
    raise RuntimeError('Task is already launched and is not completed.')
RuntimeError: Task is already launched and is not completed.
2024-09-19 19:59:18,658: - discord.app_commands.tree - ERROR - Ignoring exception in command 'smug'
Traceback (most recent call last):
  File "F:\Projetos\Yume²\.venv\Lib\site-packages\discord\app_commands\commands.py", line 827, in _do_call
    return await self._callback(self.binding, interaction, **params)  # type: ignore
           ^^^^^^^^^^^^^^^^^^^^^^^^^^^^^^^^^^^^^^^^^^^^^^^^^^^^^^^^^
  File "F:\Projetos\Yume²\cogs\actions.py", line 30, in smug
    await interaction.response.send_message(embed=embed, view=view)
  File "F:\Projetos\Yume²\.venv\Lib\site-packages\discord\interactions.py", line 786, in send_message
    params = interaction_message_response_params(
             ^^^^^^^^^^^^^^^^^^^^^^^^^^^^^^^^^^^^
  File "F:\Projetos\Yume²\.venv\Lib\site-packages\discord\webhook\async_.py", line 578, in interaction_message_response_params
    data['components'] = view.to_components()
                         ^^^^^^^^^^^^^^^^^^
AttributeError: 'Button' object has no attribute 'to_components'. Did you mean: 'from_component'?

The above exception was the direct cause of the following exception:

Traceback (most recent call last):
  File "F:\Projetos\Yume²\.venv\Lib\site-packages\discord\app_commands\tree.py", line 1248, in _call
    await command._invoke_with_namespace(interaction, namespace)
  File "F:\Projetos\Yume²\.venv\Lib\site-packages\discord\app_commands\commands.py", line 853, in _invoke_with_namespace
    return await self._do_call(interaction, transformed_values)
           ^^^^^^^^^^^^^^^^^^^^^^^^^^^^^^^^^^^^^^^^^^^^^^^^^^^^
  File "F:\Projetos\Yume²\.venv\Lib\site-packages\discord\app_commands\commands.py", line 846, in _do_call
    raise CommandInvokeError(self, e) from e
discord.app_commands.errors.CommandInvokeError: Command 'smug' raised an exception: AttributeError: 'Button' object has no attribute 'to_components'
2024-09-19 19:59:34,827: - discord.client - WARNING - PyNaCl is not installed, voice will NOT be supported
2024-09-19 19:59:34,836: - discord.client - INFO - logging in using static token
2024-09-19 19:59:36,060: - discord.gateway - INFO - Shard ID 0 has connected to Gateway (Session ID: 4497265ecd64e6eb3c138aa3bda5e4a7).
2024-09-19 19:59:38,097: - discord.client - ERROR - Ignoring exception in on_ready
Traceback (most recent call last):
  File "F:\Projetos\Yume²\.venv\Lib\site-packages\discord\client.py", line 441, in _run_event
    await coro(*args, **kwargs)
  File "F:\Projetos\Yume²\yume.py", line 47, in on_ready
    yume_status.start()
  File "F:\Projetos\Yume²\.venv\Lib\site-packages\discord\ext\tasks\__init__.py", line 392, in start
    raise RuntimeError('Task is already launched and is not completed.')
RuntimeError: Task is already launched and is not completed.
2024-09-19 19:59:40,766: - discord.app_commands.tree - ERROR - Ignoring exception in command 'smug'
Traceback (most recent call last):
  File "F:\Projetos\Yume²\.venv\Lib\site-packages\discord\app_commands\commands.py", line 827, in _do_call
    return await self._callback(self.binding, interaction, **params)  # type: ignore
           ^^^^^^^^^^^^^^^^^^^^^^^^^^^^^^^^^^^^^^^^^^^^^^^^^^^^^^^^^
  File "F:\Projetos\Yume²\cogs\actions.py", line 30, in smug
    await interaction.response.send_message(embed=embed, view=view)
  File "F:\Projetos\Yume²\.venv\Lib\site-packages\discord\interactions.py", line 786, in send_message
    params = interaction_message_response_params(
             ^^^^^^^^^^^^^^^^^^^^^^^^^^^^^^^^^^^^
  File "F:\Projetos\Yume²\.venv\Lib\site-packages\discord\webhook\async_.py", line 578, in interaction_message_response_params
    data['components'] = view.to_components()
                         ^^^^^^^^^^^^^^^^^^
AttributeError: 'function' object has no attribute 'to_components'

The above exception was the direct cause of the following exception:

Traceback (most recent call last):
  File "F:\Projetos\Yume²\.venv\Lib\site-packages\discord\app_commands\tree.py", line 1248, in _call
    await command._invoke_with_namespace(interaction, namespace)
  File "F:\Projetos\Yume²\.venv\Lib\site-packages\discord\app_commands\commands.py", line 853, in _invoke_with_namespace
    return await self._do_call(interaction, transformed_values)
           ^^^^^^^^^^^^^^^^^^^^^^^^^^^^^^^^^^^^^^^^^^^^^^^^^^^^
  File "F:\Projetos\Yume²\.venv\Lib\site-packages\discord\app_commands\commands.py", line 846, in _do_call
    raise CommandInvokeError(self, e) from e
discord.app_commands.errors.CommandInvokeError: Command 'smug' raised an exception: AttributeError: 'function' object has no attribute 'to_components'
2024-09-19 19:59:52,682: - discord.app_commands.tree - ERROR - Ignoring exception in command 'smug'
Traceback (most recent call last):
  File "F:\Projetos\Yume²\.venv\Lib\site-packages\discord\app_commands\commands.py", line 827, in _do_call
    return await self._callback(self.binding, interaction, **params)  # type: ignore
           ^^^^^^^^^^^^^^^^^^^^^^^^^^^^^^^^^^^^^^^^^^^^^^^^^^^^^^^^^
  File "F:\Projetos\Yume²\cogs\actions.py", line 30, in smug
    await interaction.response.send_message(embed=embed, view=view)
  File "F:\Projetos\Yume²\.venv\Lib\site-packages\discord\interactions.py", line 786, in send_message
    params = interaction_message_response_params(
             ^^^^^^^^^^^^^^^^^^^^^^^^^^^^^^^^^^^^
  File "F:\Projetos\Yume²\.venv\Lib\site-packages\discord\webhook\async_.py", line 578, in interaction_message_response_params
    data['components'] = view.to_components()
                         ^^^^^^^^^^^^^^^^^^
AttributeError: 'function' object has no attribute 'to_components'

The above exception was the direct cause of the following exception:

Traceback (most recent call last):
  File "F:\Projetos\Yume²\.venv\Lib\site-packages\discord\app_commands\tree.py", line 1248, in _call
    await command._invoke_with_namespace(interaction, namespace)
  File "F:\Projetos\Yume²\.venv\Lib\site-packages\discord\app_commands\commands.py", line 853, in _invoke_with_namespace
    return await self._do_call(interaction, transformed_values)
           ^^^^^^^^^^^^^^^^^^^^^^^^^^^^^^^^^^^^^^^^^^^^^^^^^^^^
  File "F:\Projetos\Yume²\.venv\Lib\site-packages\discord\app_commands\commands.py", line 846, in _do_call
    raise CommandInvokeError(self, e) from e
discord.app_commands.errors.CommandInvokeError: Command 'smug' raised an exception: AttributeError: 'function' object has no attribute 'to_components'
2024-09-19 20:00:44,627: - discord.client - WARNING - PyNaCl is not installed, voice will NOT be supported
2024-09-19 20:00:44,636: - discord.client - INFO - logging in using static token
2024-09-19 20:00:45,823: - discord.gateway - INFO - Shard ID 0 has connected to Gateway (Session ID: 909ea745f5f741449148e16c1cfd8e3a).
2024-09-19 20:00:47,850: - discord.client - ERROR - Ignoring exception in on_ready
Traceback (most recent call last):
  File "F:\Projetos\Yume²\.venv\Lib\site-packages\discord\client.py", line 441, in _run_event
    await coro(*args, **kwargs)
  File "F:\Projetos\Yume²\yume.py", line 47, in on_ready
    yume_status.start()
  File "F:\Projetos\Yume²\.venv\Lib\site-packages\discord\ext\tasks\__init__.py", line 392, in start
    raise RuntimeError('Task is already launched and is not completed.')
RuntimeError: Task is already launched and is not completed.
2024-09-19 20:00:54,633: - discord.app_commands.tree - ERROR - Ignoring exception in command 'smug'
Traceback (most recent call last):
  File "F:\Projetos\Yume²\.venv\Lib\site-packages\discord\app_commands\commands.py", line 827, in _do_call
    return await self._callback(self.binding, interaction, **params)  # type: ignore
           ^^^^^^^^^^^^^^^^^^^^^^^^^^^^^^^^^^^^^^^^^^^^^^^^^^^^^^^^^
  File "F:\Projetos\Yume²\cogs\actions.py", line 30, in smug
    await interaction.response.send_message(embed=embed, view=view)
  File "F:\Projetos\Yume²\.venv\Lib\site-packages\discord\interactions.py", line 786, in send_message
    params = interaction_message_response_params(
             ^^^^^^^^^^^^^^^^^^^^^^^^^^^^^^^^^^^^
  File "F:\Projetos\Yume²\.venv\Lib\site-packages\discord\webhook\async_.py", line 578, in interaction_message_response_params
    data['components'] = view.to_components()
                         ^^^^^^^^^^^^^^^^^^
AttributeError: 'function' object has no attribute 'to_components'

The above exception was the direct cause of the following exception:

Traceback (most recent call last):
  File "F:\Projetos\Yume²\.venv\Lib\site-packages\discord\app_commands\tree.py", line 1248, in _call
    await command._invoke_with_namespace(interaction, namespace)
  File "F:\Projetos\Yume²\.venv\Lib\site-packages\discord\app_commands\commands.py", line 853, in _invoke_with_namespace
    return await self._do_call(interaction, transformed_values)
           ^^^^^^^^^^^^^^^^^^^^^^^^^^^^^^^^^^^^^^^^^^^^^^^^^^^^
  File "F:\Projetos\Yume²\.venv\Lib\site-packages\discord\app_commands\commands.py", line 846, in _do_call
    raise CommandInvokeError(self, e) from e
discord.app_commands.errors.CommandInvokeError: Command 'smug' raised an exception: AttributeError: 'function' object has no attribute 'to_components'
2024-09-19 20:01:10,114: - discord.client - WARNING - PyNaCl is not installed, voice will NOT be supported
2024-09-19 20:01:10,122: - discord.client - INFO - logging in using static token
2024-09-19 20:01:11,548: - discord.gateway - INFO - Shard ID 0 has connected to Gateway (Session ID: 38cb9cbc9c1d45c4661ce006573a8942).
2024-09-19 20:01:13,578: - discord.client - ERROR - Ignoring exception in on_ready
Traceback (most recent call last):
  File "F:\Projetos\Yume²\.venv\Lib\site-packages\discord\client.py", line 441, in _run_event
    await coro(*args, **kwargs)
  File "F:\Projetos\Yume²\yume.py", line 47, in on_ready
    yume_status.start()
  File "F:\Projetos\Yume²\.venv\Lib\site-packages\discord\ext\tasks\__init__.py", line 392, in start
    raise RuntimeError('Task is already launched and is not completed.')
RuntimeError: Task is already launched and is not completed.
2024-09-19 20:01:46,964: - discord.app_commands.tree - ERROR - Ignoring exception in command 'smug'
Traceback (most recent call last):
  File "F:\Projetos\Yume²\.venv\Lib\site-packages\discord\app_commands\commands.py", line 827, in _do_call
    return await self._callback(self.binding, interaction, **params)  # type: ignore
           ^^^^^^^^^^^^^^^^^^^^^^^^^^^^^^^^^^^^^^^^^^^^^^^^^^^^^^^^^
  File "F:\Projetos\Yume²\cogs\actions.py", line 29, in smug
    view = buttons.smug_button()
           ^^^^^^^^^^^^^^^^^^^^^
TypeError: smug_button() missing 3 required positional arguments: 'self', 'interaction', and 'button'

The above exception was the direct cause of the following exception:

Traceback (most recent call last):
  File "F:\Projetos\Yume²\.venv\Lib\site-packages\discord\app_commands\tree.py", line 1248, in _call
    await command._invoke_with_namespace(interaction, namespace)
  File "F:\Projetos\Yume²\.venv\Lib\site-packages\discord\app_commands\commands.py", line 853, in _invoke_with_namespace
    return await self._do_call(interaction, transformed_values)
           ^^^^^^^^^^^^^^^^^^^^^^^^^^^^^^^^^^^^^^^^^^^^^^^^^^^^
  File "F:\Projetos\Yume²\.venv\Lib\site-packages\discord\app_commands\commands.py", line 842, in _do_call
    raise CommandInvokeError(self, e) from e
discord.app_commands.errors.CommandInvokeError: Command 'smug' raised an exception: TypeError: smug_button() missing 3 required positional arguments: 'self', 'interaction', and 'button'
2024-09-19 20:01:56,533: - discord.app_commands.tree - ERROR - Ignoring exception in command 'smug'
Traceback (most recent call last):
  File "F:\Projetos\Yume²\.venv\Lib\site-packages\discord\app_commands\commands.py", line 827, in _do_call
    return await self._callback(self.binding, interaction, **params)  # type: ignore
           ^^^^^^^^^^^^^^^^^^^^^^^^^^^^^^^^^^^^^^^^^^^^^^^^^^^^^^^^^
  File "F:\Projetos\Yume²\cogs\actions.py", line 29, in smug
    view = buttons.smug_button()
           ^^^^^^^^^^^^^^^^^^^^^
TypeError: smug_button() missing 3 required positional arguments: 'self', 'interaction', and 'button'

The above exception was the direct cause of the following exception:

Traceback (most recent call last):
  File "F:\Projetos\Yume²\.venv\Lib\site-packages\discord\app_commands\tree.py", line 1248, in _call
    await command._invoke_with_namespace(interaction, namespace)
  File "F:\Projetos\Yume²\.venv\Lib\site-packages\discord\app_commands\commands.py", line 853, in _invoke_with_namespace
    return await self._do_call(interaction, transformed_values)
           ^^^^^^^^^^^^^^^^^^^^^^^^^^^^^^^^^^^^^^^^^^^^^^^^^^^^
  File "F:\Projetos\Yume²\.venv\Lib\site-packages\discord\app_commands\commands.py", line 842, in _do_call
    raise CommandInvokeError(self, e) from e
discord.app_commands.errors.CommandInvokeError: Command 'smug' raised an exception: TypeError: smug_button() missing 3 required positional arguments: 'self', 'interaction', and 'button'
2024-09-19 20:13:51,184: - discord.client - WARNING - PyNaCl is not installed, voice will NOT be supported
2024-09-19 20:13:51,192: - discord.client - INFO - logging in using static token
2024-09-19 20:13:52,498: - discord.gateway - INFO - Shard ID 0 has connected to Gateway (Session ID: 6509127e8c24ffb3469c15a1ba428c65).
2024-09-19 20:13:54,547: - discord.client - ERROR - Ignoring exception in on_ready
Traceback (most recent call last):
  File "F:\Projetos\Yume²\.venv\Lib\site-packages\discord\client.py", line 441, in _run_event
    await coro(*args, **kwargs)
  File "F:\Projetos\Yume²\yume.py", line 47, in on_ready
    yume_status.start()
  File "F:\Projetos\Yume²\.venv\Lib\site-packages\discord\ext\tasks\__init__.py", line 392, in start
    raise RuntimeError('Task is already launched and is not completed.')
RuntimeError: Task is already launched and is not completed.
2024-09-20 21:50:10,780: - discord.client - WARNING - PyNaCl is not installed, voice will NOT be supported
2024-09-20 21:50:10,794: - discord.client - INFO - logging in using static token
2024-09-20 21:50:12,055: - discord.gateway - INFO - Shard ID 0 has connected to Gateway (Session ID: 620671f2c16a7ceb26c9e3574895add2).
2024-09-20 21:50:14,077: - discord.client - ERROR - Ignoring exception in on_ready
Traceback (most recent call last):
  File "F:\Projetos\Yume²\.venv\Lib\site-packages\discord\client.py", line 441, in _run_event
    await coro(*args, **kwargs)
  File "F:\Projetos\Yume²\yume.py", line 47, in on_ready
    yume_status.start()
  File "F:\Projetos\Yume²\.venv\Lib\site-packages\discord\ext\tasks\__init__.py", line 392, in start
    raise RuntimeError('Task is already launched and is not completed.')
RuntimeError: Task is already launched and is not completed.
2024-09-20 23:38:42,411: - discord.client - WARNING - PyNaCl is not installed, voice will NOT be supported
2024-09-20 23:38:58,884: - discord.client - WARNING - PyNaCl is not installed, voice will NOT be supported
2024-09-20 23:38:59,188: - discord.client - INFO - logging in using static token
2024-09-20 23:39:00,515: - discord.gateway - INFO - Shard ID 0 has connected to Gateway (Session ID: 3cb9676a9b56493a6082e4b8e1d16f6b).
2024-09-20 23:39:02,667: - discord.client - ERROR - Ignoring exception in on_ready
Traceback (most recent call last):
  File "F:\Projetos\Yume²\.venv\Lib\site-packages\discord\client.py", line 441, in _run_event
    await coro(*args, **kwargs)
  File "F:\Projetos\Yume²\yume.py", line 48, in on_ready
    yume_status.start()
  File "F:\Projetos\Yume²\.venv\Lib\site-packages\discord\ext\tasks\__init__.py", line 392, in start
    raise RuntimeError('Task is already launched and is not completed.')
RuntimeError: Task is already launched and is not completed.
2024-09-20 23:40:19,376: - discord.client - WARNING - PyNaCl is not installed, voice will NOT be supported
2024-09-20 23:40:19,713: - discord.client - INFO - logging in using static token
2024-09-20 23:40:20,753: - discord.gateway - INFO - Shard ID 0 has connected to Gateway (Session ID: 3ca3cd8bc7b20ee61a5892dfe4b96177).
2024-09-20 23:40:22,767: - discord.client - ERROR - Ignoring exception in on_ready
Traceback (most recent call last):
  File "F:\Projetos\Yume²\.venv\Lib\site-packages\discord\client.py", line 441, in _run_event
    await coro(*args, **kwargs)
  File "F:\Projetos\Yume²\yume.py", line 48, in on_ready
    yume_status.start()
  File "F:\Projetos\Yume²\.venv\Lib\site-packages\discord\ext\tasks\__init__.py", line 392, in start
    raise RuntimeError('Task is already launched and is not completed.')
RuntimeError: Task is already launched and is not completed.
2024-09-21 00:48:40,491: - discord.client - WARNING - PyNaCl is not installed, voice will NOT be supported
2024-09-21 00:48:40,760: - discord.client - INFO - logging in using static token
2024-09-21 00:48:41,770: - discord.gateway - INFO - Shard ID 0 has connected to Gateway (Session ID: 7b44900b5d36afca900da6d99ebf76e5).
2024-09-21 00:48:43,808: - discord.client - ERROR - Ignoring exception in on_ready
Traceback (most recent call last):
  File "F:\Projetos\Yume²\.venv\Lib\site-packages\discord\client.py", line 441, in _run_event
    await coro(*args, **kwargs)
  File "F:\Projetos\Yume²\yume.py", line 48, in on_ready
    yume_status.start()
  File "F:\Projetos\Yume²\.venv\Lib\site-packages\discord\ext\tasks\__init__.py", line 392, in start
    raise RuntimeError('Task is already launched and is not completed.')
RuntimeError: Task is already launched and is not completed.
2024-09-21 00:49:25,032: - discord.app_commands.tree - ERROR - Ignoring exception in command 'hug'
Traceback (most recent call last):
  File "F:\Projetos\Yume²\.venv\Lib\site-packages\discord\app_commands\commands.py", line 827, in _do_call
    return await self._callback(self.binding, interaction, **params)  # type: ignore
           ^^^^^^^^^^^^^^^^^^^^^^^^^^^^^^^^^^^^^^^^^^^^^^^^^^^^^^^^^
  File "F:\Projetos\Yume²\cogs\roleplay.py", line 33, in hug
    await interaction.response.send_message(embed=GenericEmbed.embed)
  File "F:\Projetos\Yume²\.venv\Lib\site-packages\discord\interactions.py", line 801, in send_message
    await adapter.create_interaction_response(
  File "F:\Projetos\Yume²\.venv\Lib\site-packages\discord\webhook\async_.py", line 221, in request
    raise HTTPException(response, data)
discord.errors.HTTPException: 400 Bad Request (error code: 50035): Invalid Form Body
In data.embeds.0.image.url: Not a well formed URL.

The above exception was the direct cause of the following exception:

Traceback (most recent call last):
  File "F:\Projetos\Yume²\.venv\Lib\site-packages\discord\app_commands\tree.py", line 1248, in _call
    await command._invoke_with_namespace(interaction, namespace)
  File "F:\Projetos\Yume²\.venv\Lib\site-packages\discord\app_commands\commands.py", line 853, in _invoke_with_namespace
    return await self._do_call(interaction, transformed_values)
           ^^^^^^^^^^^^^^^^^^^^^^^^^^^^^^^^^^^^^^^^^^^^^^^^^^^^
  File "F:\Projetos\Yume²\.venv\Lib\site-packages\discord\app_commands\commands.py", line 846, in _do_call
    raise CommandInvokeError(self, e) from e
discord.app_commands.errors.CommandInvokeError: Command 'hug' raised an exception: HTTPException: 400 Bad Request (error code: 50035): Invalid Form Body
In data.embeds.0.image.url: Not a well formed URL.
2024-09-21 00:49:50,610: - discord.client - WARNING - PyNaCl is not installed, voice will NOT be supported
2024-09-21 00:49:50,857: - discord.client - INFO - logging in using static token
2024-09-21 00:49:51,910: - discord.gateway - INFO - Shard ID 0 has connected to Gateway (Session ID: d7e65b412888ec01f48bf47dda20dae4).
2024-09-21 00:49:53,951: - discord.client - ERROR - Ignoring exception in on_ready
Traceback (most recent call last):
  File "F:\Projetos\Yume²\.venv\Lib\site-packages\discord\client.py", line 441, in _run_event
    await coro(*args, **kwargs)
  File "F:\Projetos\Yume²\yume.py", line 48, in on_ready
    yume_status.start()
  File "F:\Projetos\Yume²\.venv\Lib\site-packages\discord\ext\tasks\__init__.py", line 392, in start
    raise RuntimeError('Task is already launched and is not completed.')
RuntimeError: Task is already launched and is not completed.
2024-09-21 00:51:23,367: - discord.client - WARNING - PyNaCl is not installed, voice will NOT be supported
2024-09-21 00:51:23,614: - discord.client - INFO - logging in using static token
2024-09-21 00:51:24,848: - discord.gateway - INFO - Shard ID 0 has connected to Gateway (Session ID: d080afc5cdd6f19ca016f4784da95642).
2024-09-21 00:51:26,869: - discord.client - ERROR - Ignoring exception in on_ready
Traceback (most recent call last):
  File "F:\Projetos\Yume²\.venv\Lib\site-packages\discord\client.py", line 441, in _run_event
    await coro(*args, **kwargs)
  File "F:\Projetos\Yume²\yume.py", line 48, in on_ready
    yume_status.start()
  File "F:\Projetos\Yume²\.venv\Lib\site-packages\discord\ext\tasks\__init__.py", line 392, in start
    raise RuntimeError('Task is already launched and is not completed.')
RuntimeError: Task is already launched and is not completed.
2024-09-21 00:51:38,746: - discord.app_commands.tree - ERROR - Ignoring exception in command 'hug'
Traceback (most recent call last):
  File "F:\Projetos\Yume²\.venv\Lib\site-packages\discord\app_commands\commands.py", line 827, in _do_call
    return await self._callback(self.binding, interaction, **params)  # type: ignore
           ^^^^^^^^^^^^^^^^^^^^^^^^^^^^^^^^^^^^^^^^^^^^^^^^^^^^^^^^^
  File "F:\Projetos\Yume²\cogs\roleplay.py", line 28, in hug
    GenericEmbed.embed.set_footer(text='Just lovely!!!', icon_url=bot.user.avatar_url)
                                                                  ^^^^^^^^
AttributeError: module 'discord.ext.commands.bot' has no attribute 'user'

The above exception was the direct cause of the following exception:

Traceback (most recent call last):
  File "F:\Projetos\Yume²\.venv\Lib\site-packages\discord\app_commands\tree.py", line 1248, in _call
    await command._invoke_with_namespace(interaction, namespace)
  File "F:\Projetos\Yume²\.venv\Lib\site-packages\discord\app_commands\commands.py", line 853, in _invoke_with_namespace
    return await self._do_call(interaction, transformed_values)
           ^^^^^^^^^^^^^^^^^^^^^^^^^^^^^^^^^^^^^^^^^^^^^^^^^^^^
  File "F:\Projetos\Yume²\.venv\Lib\site-packages\discord\app_commands\commands.py", line 846, in _do_call
    raise CommandInvokeError(self, e) from e
discord.app_commands.errors.CommandInvokeError: Command 'hug' raised an exception: AttributeError: module 'discord.ext.commands.bot' has no attribute 'user'
2024-09-21 00:52:05,148: - discord.client - WARNING - PyNaCl is not installed, voice will NOT be supported
2024-09-21 00:52:05,367: - discord.client - INFO - logging in using static token
2024-09-21 00:52:06,454: - discord.gateway - INFO - Shard ID 0 has connected to Gateway (Session ID: b73c4f53e01a1363d8821dac6d76f73f).
2024-09-21 00:52:08,483: - discord.client - ERROR - Ignoring exception in on_ready
Traceback (most recent call last):
  File "F:\Projetos\Yume²\.venv\Lib\site-packages\discord\client.py", line 441, in _run_event
    await coro(*args, **kwargs)
  File "F:\Projetos\Yume²\yume.py", line 48, in on_ready
    yume_status.start()
  File "F:\Projetos\Yume²\.venv\Lib\site-packages\discord\ext\tasks\__init__.py", line 392, in start
    raise RuntimeError('Task is already launched and is not completed.')
RuntimeError: Task is already launched and is not completed.
2024-09-21 00:52:14,916: - discord.app_commands.tree - ERROR - Ignoring exception in command 'hug'
Traceback (most recent call last):
  File "F:\Projetos\Yume²\.venv\Lib\site-packages\discord\app_commands\commands.py", line 827, in _do_call
    return await self._callback(self.binding, interaction, **params)  # type: ignore
           ^^^^^^^^^^^^^^^^^^^^^^^^^^^^^^^^^^^^^^^^^^^^^^^^^^^^^^^^^
  File "F:\Projetos\Yume²\cogs\roleplay.py", line 28, in hug
    GenericEmbed.embed.set_footer(text='Just lovely!!!', icon_url=self.yume.user.avatar_url)
                                                                  ^^^^^^^^^^^^^^^^^^^^^^^^^
AttributeError: 'ClientUser' object has no attribute 'avatar_url'

The above exception was the direct cause of the following exception:

Traceback (most recent call last):
  File "F:\Projetos\Yume²\.venv\Lib\site-packages\discord\app_commands\tree.py", line 1248, in _call
    await command._invoke_with_namespace(interaction, namespace)
  File "F:\Projetos\Yume²\.venv\Lib\site-packages\discord\app_commands\commands.py", line 853, in _invoke_with_namespace
    return await self._do_call(interaction, transformed_values)
           ^^^^^^^^^^^^^^^^^^^^^^^^^^^^^^^^^^^^^^^^^^^^^^^^^^^^
  File "F:\Projetos\Yume²\.venv\Lib\site-packages\discord\app_commands\commands.py", line 846, in _do_call
    raise CommandInvokeError(self, e) from e
discord.app_commands.errors.CommandInvokeError: Command 'hug' raised an exception: AttributeError: 'ClientUser' object has no attribute 'avatar_url'
2024-09-21 00:52:29,346: - discord.client - WARNING - PyNaCl is not installed, voice will NOT be supported
2024-09-21 00:52:29,639: - discord.client - INFO - logging in using static token
2024-09-21 00:52:30,880: - discord.gateway - INFO - Shard ID 0 has connected to Gateway (Session ID: 92795414d01290d70ee78603659e4eff).
2024-09-21 00:52:32,907: - discord.client - ERROR - Ignoring exception in on_ready
Traceback (most recent call last):
  File "F:\Projetos\Yume²\.venv\Lib\site-packages\discord\client.py", line 441, in _run_event
    await coro(*args, **kwargs)
  File "F:\Projetos\Yume²\yume.py", line 48, in on_ready
    yume_status.start()
  File "F:\Projetos\Yume²\.venv\Lib\site-packages\discord\ext\tasks\__init__.py", line 392, in start
    raise RuntimeError('Task is already launched and is not completed.')
RuntimeError: Task is already launched and is not completed.
2024-09-21 00:52:49,250: - discord.app_commands.tree - ERROR - Ignoring exception in command 'hug'
Traceback (most recent call last):
  File "F:\Projetos\Yume²\.venv\Lib\site-packages\discord\app_commands\commands.py", line 827, in _do_call
    return await self._callback(self.binding, interaction, **params)  # type: ignore
           ^^^^^^^^^^^^^^^^^^^^^^^^^^^^^^^^^^^^^^^^^^^^^^^^^^^^^^^^^
  File "F:\Projetos\Yume²\cogs\roleplay.py", line 28, in hug
    GenericEmbed.embed.set_footer(text='Just lovely!!!', icon_url=self.bot.user.avatar_url)
                                                                  ^^^^^^^^
AttributeError: 'RolePlay' object has no attribute 'bot'

The above exception was the direct cause of the following exception:

Traceback (most recent call last):
  File "F:\Projetos\Yume²\.venv\Lib\site-packages\discord\app_commands\tree.py", line 1248, in _call
    await command._invoke_with_namespace(interaction, namespace)
  File "F:\Projetos\Yume²\.venv\Lib\site-packages\discord\app_commands\commands.py", line 853, in _invoke_with_namespace
    return await self._do_call(interaction, transformed_values)
           ^^^^^^^^^^^^^^^^^^^^^^^^^^^^^^^^^^^^^^^^^^^^^^^^^^^^
  File "F:\Projetos\Yume²\.venv\Lib\site-packages\discord\app_commands\commands.py", line 846, in _do_call
    raise CommandInvokeError(self, e) from e
discord.app_commands.errors.CommandInvokeError: Command 'hug' raised an exception: AttributeError: 'RolePlay' object has no attribute 'bot'
2024-09-21 01:46:28,286: - discord.client - WARNING - PyNaCl is not installed, voice will NOT be supported
2024-09-21 01:46:28,519: - discord.client - INFO - logging in using static token
2024-09-21 01:46:29,575: - discord.gateway - INFO - Shard ID 0 has connected to Gateway (Session ID: 8145fcbab6e52365146e3c61280a4e33).
2024-09-21 01:46:31,594: - discord.client - ERROR - Ignoring exception in on_ready
Traceback (most recent call last):
  File "F:\Projetos\Yume²\.venv\Lib\site-packages\discord\client.py", line 441, in _run_event
    await coro(*args, **kwargs)
  File "F:\Projetos\Yume²\yume.py", line 48, in on_ready
    yume_status.start()
  File "F:\Projetos\Yume²\.venv\Lib\site-packages\discord\ext\tasks\__init__.py", line 392, in start
    raise RuntimeError('Task is already launched and is not completed.')
RuntimeError: Task is already launched and is not completed.
2024-09-21 01:47:21,047: - discord.app_commands.tree - ERROR - Ignoring exception in command 'boop'
Traceback (most recent call last):
  File "F:\Projetos\Yume²\.venv\Lib\site-packages\discord\app_commands\commands.py", line 827, in _do_call
    return await self._callback(self.binding, interaction, **params)  # type: ignore
           ^^^^^^^^^^^^^^^^^^^^^^^^^^^^^^^^^^^^^^^^^^^^^^^^^^^^^^^^^
  File "F:\Projetos\Yume²\cogs\roleplay.py", line 207, in boop
    GenericEmbed.embed.set_image(url=str(await helpers.nekos_best()))
                                         ^^^^^^^^^^^^^^^^^^^^^^^^^^
  File "F:\Projetos\Yume²\utils\helpers.py", line 59, in nekos_best
    return data['results'][0]['url']
           ~~~~^^^^^^^^^^^
KeyError: 'results'

The above exception was the direct cause of the following exception:

Traceback (most recent call last):
  File "F:\Projetos\Yume²\.venv\Lib\site-packages\discord\app_commands\tree.py", line 1248, in _call
    await command._invoke_with_namespace(interaction, namespace)
  File "F:\Projetos\Yume²\.venv\Lib\site-packages\discord\app_commands\commands.py", line 853, in _invoke_with_namespace
    return await self._do_call(interaction, transformed_values)
           ^^^^^^^^^^^^^^^^^^^^^^^^^^^^^^^^^^^^^^^^^^^^^^^^^^^^
  File "F:\Projetos\Yume²\.venv\Lib\site-packages\discord\app_commands\commands.py", line 846, in _do_call
    raise CommandInvokeError(self, e) from e
discord.app_commands.errors.CommandInvokeError: Command 'boop' raised an exception: KeyError: 'results'
2024-09-21 01:48:18,903: - discord.app_commands.tree - ERROR - Ignoring exception in command 'lick'
Traceback (most recent call last):
  File "F:\Projetos\Yume²\.venv\Lib\site-packages\discord\app_commands\commands.py", line 827, in _do_call
    return await self._callback(self.binding, interaction, **params)  # type: ignore
           ^^^^^^^^^^^^^^^^^^^^^^^^^^^^^^^^^^^^^^^^^^^^^^^^^^^^^^^^^
  File "F:\Projetos\Yume²\cogs\roleplay.py", line 177, in lick
    GenericEmbed.embed.set_image(url=str(await helpers.nekos_best()))
                                         ^^^^^^^^^^^^^^^^^^^^^^^^^^
  File "F:\Projetos\Yume²\utils\helpers.py", line 59, in nekos_best
    return data['results'][0]['url']
           ~~~~^^^^^^^^^^^
KeyError: 'results'

The above exception was the direct cause of the following exception:

Traceback (most recent call last):
  File "F:\Projetos\Yume²\.venv\Lib\site-packages\discord\app_commands\tree.py", line 1248, in _call
    await command._invoke_with_namespace(interaction, namespace)
  File "F:\Projetos\Yume²\.venv\Lib\site-packages\discord\app_commands\commands.py", line 853, in _invoke_with_namespace
    return await self._do_call(interaction, transformed_values)
           ^^^^^^^^^^^^^^^^^^^^^^^^^^^^^^^^^^^^^^^^^^^^^^^^^^^^
  File "F:\Projetos\Yume²\.venv\Lib\site-packages\discord\app_commands\commands.py", line 846, in _do_call
    raise CommandInvokeError(self, e) from e
discord.app_commands.errors.CommandInvokeError: Command 'lick' raised an exception: KeyError: 'results'
2024-09-21 01:49:43,772: - discord.app_commands.tree - ERROR - Ignoring exception in command 'stomp'
Traceback (most recent call last):
  File "F:\Projetos\Yume²\.venv\Lib\site-packages\discord\app_commands\commands.py", line 827, in _do_call
    return await self._callback(self.binding, interaction, **params)  # type: ignore
           ^^^^^^^^^^^^^^^^^^^^^^^^^^^^^^^^^^^^^^^^^^^^^^^^^^^^^^^^^
  File "F:\Projetos\Yume²\cogs\roleplay.py", line 192, in stomp
    # Realiza o registro da classe nos cogs
                                            
  File "F:\Projetos\Yume²\utils\helpers.py", line 59, in nekos_best
    return data['results'][0]['url']
           ~~~~^^^^^^^^^^^
KeyError: 'results'

The above exception was the direct cause of the following exception:

Traceback (most recent call last):
  File "F:\Projetos\Yume²\.venv\Lib\site-packages\discord\app_commands\tree.py", line 1248, in _call
    await command._invoke_with_namespace(interaction, namespace)
  File "F:\Projetos\Yume²\.venv\Lib\site-packages\discord\app_commands\commands.py", line 853, in _invoke_with_namespace
    return await self._do_call(interaction, transformed_values)
           ^^^^^^^^^^^^^^^^^^^^^^^^^^^^^^^^^^^^^^^^^^^^^^^^^^^^
  File "F:\Projetos\Yume²\.venv\Lib\site-packages\discord\app_commands\commands.py", line 846, in _do_call
    raise CommandInvokeError(self, e) from e
discord.app_commands.errors.CommandInvokeError: Command 'stomp' raised an exception: KeyError: 'results'
2024-09-21 02:27:16,425: - discord.client - WARNING - PyNaCl is not installed, voice will NOT be supported
2024-09-21 02:27:32,912: - discord.client - WARNING - PyNaCl is not installed, voice will NOT be supported
2024-09-21 02:27:33,173: - discord.client - INFO - logging in using static token
2024-09-21 02:27:34,307: - discord.gateway - INFO - Shard ID 0 has connected to Gateway (Session ID: 4e05d395e6026905bf888b9329eae5ec).
2024-09-21 02:27:36,324: - discord.client - ERROR - Ignoring exception in on_ready
Traceback (most recent call last):
  File "F:\Projetos\Yume²\.venv\Lib\site-packages\discord\client.py", line 441, in _run_event
    await coro(*args, **kwargs)
  File "F:\Projetos\Yume²\yume.py", line 48, in on_ready
    yume_status.start()
  File "F:\Projetos\Yume²\.venv\Lib\site-packages\discord\ext\tasks\__init__.py", line 392, in start
    raise RuntimeError('Task is already launched and is not completed.')
RuntimeError: Task is already launched and is not completed.
2024-09-21 02:28:05,612: - discord.app_commands.tree - ERROR - Ignoring exception in command 'info'
Traceback (most recent call last):
  File "F:\Projetos\Yume²\.venv\Lib\site-packages\discord\app_commands\commands.py", line 827, in _do_call
    return await self._callback(self.binding, interaction, **params)  # type: ignore
           ^^^^^^^^^^^^^^^^^^^^^^^^^^^^^^^^^^^^^^^^^^^^^^^^^^^^^^^^^
  File "F:\Projetos\Yume²\cogs\dreams.py", line 30, in info
    await interaction.response.send_message(embed=embeds.InfoEmbed.iembed, ephemeral=True)
                                                  ^^^^^^
NameError: name 'embeds' is not defined

The above exception was the direct cause of the following exception:

Traceback (most recent call last):
  File "F:\Projetos\Yume²\.venv\Lib\site-packages\discord\app_commands\tree.py", line 1248, in _call
    await command._invoke_with_namespace(interaction, namespace)
  File "F:\Projetos\Yume²\.venv\Lib\site-packages\discord\app_commands\commands.py", line 853, in _invoke_with_namespace
    return await self._do_call(interaction, transformed_values)
           ^^^^^^^^^^^^^^^^^^^^^^^^^^^^^^^^^^^^^^^^^^^^^^^^^^^^
  File "F:\Projetos\Yume²\.venv\Lib\site-packages\discord\app_commands\commands.py", line 846, in _do_call
    raise CommandInvokeError(self, e) from e
discord.app_commands.errors.CommandInvokeError: Command 'info' raised an exception: NameError: name 'embeds' is not defined
2024-09-21 02:28:52,750: - discord.client - WARNING - PyNaCl is not installed, voice will NOT be supported
2024-09-21 02:28:53,000: - discord.client - INFO - logging in using static token
2024-09-21 02:28:54,118: - discord.gateway - INFO - Shard ID 0 has connected to Gateway (Session ID: 587390d055840fe5eb4b494d53c85926).
2024-09-21 02:28:56,127: - discord.client - ERROR - Ignoring exception in on_ready
Traceback (most recent call last):
  File "F:\Projetos\Yume²\.venv\Lib\site-packages\discord\client.py", line 441, in _run_event
    await coro(*args, **kwargs)
  File "F:\Projetos\Yume²\yume.py", line 48, in on_ready
    yume_status.start()
  File "F:\Projetos\Yume²\.venv\Lib\site-packages\discord\ext\tasks\__init__.py", line 392, in start
    raise RuntimeError('Task is already launched and is not completed.')
RuntimeError: Task is already launched and is not completed.
2024-09-21 02:29:24,039: - discord.app_commands.tree - ERROR - Ignoring exception in command 'invite'
Traceback (most recent call last):
  File "F:\Projetos\Yume²\.venv\Lib\site-packages\discord\app_commands\commands.py", line 827, in _do_call
    return await self._callback(self.binding, interaction, **params)  # type: ignore
           ^^^^^^^^^^^^^^^^^^^^^^^^^^^^^^^^^^^^^^^^^^^^^^^^^^^^^^^^^
  File "F:\Projetos\Yume²\cogs\dreams.py", line 36, in invite
    await interaction.response.send_message(embed=GenericEmbed.embed, ephemeral=True)
  File "F:\Projetos\Yume²\.venv\Lib\site-packages\discord\interactions.py", line 801, in send_message
    await adapter.create_interaction_response(
  File "F:\Projetos\Yume²\.venv\Lib\site-packages\discord\webhook\async_.py", line 221, in request
    raise HTTPException(response, data)
discord.errors.HTTPException: 400 Bad Request (error code: 50035): Invalid Form Body
In data.embeds.0.description: This field is required

The above exception was the direct cause of the following exception:

Traceback (most recent call last):
  File "F:\Projetos\Yume²\.venv\Lib\site-packages\discord\app_commands\tree.py", line 1248, in _call
    await command._invoke_with_namespace(interaction, namespace)
  File "F:\Projetos\Yume²\.venv\Lib\site-packages\discord\app_commands\commands.py", line 853, in _invoke_with_namespace
    return await self._do_call(interaction, transformed_values)
           ^^^^^^^^^^^^^^^^^^^^^^^^^^^^^^^^^^^^^^^^^^^^^^^^^^^^
  File "F:\Projetos\Yume²\.venv\Lib\site-packages\discord\app_commands\commands.py", line 846, in _do_call
    raise CommandInvokeError(self, e) from e
discord.app_commands.errors.CommandInvokeError: Command 'invite' raised an exception: HTTPException: 400 Bad Request (error code: 50035): Invalid Form Body
In data.embeds.0.description: This field is required
2024-09-21 02:30:00,670: - discord.app_commands.tree - ERROR - Ignoring exception in command 'typo'
Traceback (most recent call last):
  File "F:\Projetos\Yume²\.venv\Lib\site-packages\discord\app_commands\commands.py", line 827, in _do_call
    return await self._callback(self.binding, interaction, **params)  # type: ignore
           ^^^^^^^^^^^^^^^^^^^^^^^^^^^^^^^^^^^^^^^^^^^^^^^^^^^^^^^^^
  File "F:\Projetos\Yume²\cogs\dreams.py", line 43, in typo
TypeError: InteractionResponse.send_modal() got an unexpected keyword argument 'ephemeral'

The above exception was the direct cause of the following exception:

Traceback (most recent call last):
  File "F:\Projetos\Yume²\.venv\Lib\site-packages\discord\app_commands\tree.py", line 1248, in _call
    await command._invoke_with_namespace(interaction, namespace)
  File "F:\Projetos\Yume²\.venv\Lib\site-packages\discord\app_commands\commands.py", line 853, in _invoke_with_namespace
    return await self._do_call(interaction, transformed_values)
           ^^^^^^^^^^^^^^^^^^^^^^^^^^^^^^^^^^^^^^^^^^^^^^^^^^^^
  File "F:\Projetos\Yume²\.venv\Lib\site-packages\discord\app_commands\commands.py", line 842, in _do_call
    raise CommandInvokeError(self, e) from e
discord.app_commands.errors.CommandInvokeError: Command 'typo' raised an exception: TypeError: InteractionResponse.send_modal() got an unexpected keyword argument 'ephemeral'
2024-09-21 02:30:20,026: - discord.client - WARNING - PyNaCl is not installed, voice will NOT be supported
2024-09-21 02:30:20,269: - discord.client - INFO - logging in using static token
2024-09-21 02:30:21,280: - discord.gateway - INFO - Shard ID 0 has connected to Gateway (Session ID: a1133b98bac5a871816f5e6d8ede343e).
2024-09-21 02:30:23,313: - discord.client - ERROR - Ignoring exception in on_ready
Traceback (most recent call last):
  File "F:\Projetos\Yume²\.venv\Lib\site-packages\discord\client.py", line 441, in _run_event
    await coro(*args, **kwargs)
  File "F:\Projetos\Yume²\yume.py", line 48, in on_ready
    yume_status.start()
  File "F:\Projetos\Yume²\.venv\Lib\site-packages\discord\ext\tasks\__init__.py", line 392, in start
    raise RuntimeError('Task is already launched and is not completed.')
RuntimeError: Task is already launched and is not completed.
2024-09-21 02:34:29,806: - discord.client - WARNING - PyNaCl is not installed, voice will NOT be supported
2024-09-21 02:34:30,067: - discord.client - INFO - logging in using static token
2024-09-21 02:34:31,133: - discord.gateway - INFO - Shard ID 0 has connected to Gateway (Session ID: 729c8c2a85cca882e2b7ac3bb8cb40ff).
2024-09-21 02:34:33,160: - discord.client - ERROR - Ignoring exception in on_ready
Traceback (most recent call last):
  File "F:\Projetos\Yume²\.venv\Lib\site-packages\discord\client.py", line 441, in _run_event
    await coro(*args, **kwargs)
  File "F:\Projetos\Yume²\yume.py", line 48, in on_ready
    yume_status.start()
  File "F:\Projetos\Yume²\.venv\Lib\site-packages\discord\ext\tasks\__init__.py", line 392, in start
    raise RuntimeError('Task is already launched and is not completed.')
RuntimeError: Task is already launched and is not completed.
2024-09-21 02:35:04,577: - discord.client - WARNING - PyNaCl is not installed, voice will NOT be supported
2024-09-21 02:35:04,999: - discord.client - INFO - logging in using static token
2024-09-21 02:35:05,986: - discord.gateway - INFO - Shard ID 0 has connected to Gateway (Session ID: 23a33b40bd1e76f7448f11d4842e3aaa).
2024-09-21 02:35:07,993: - discord.client - ERROR - Ignoring exception in on_ready
Traceback (most recent call last):
  File "F:\Projetos\Yume²\.venv\Lib\site-packages\discord\client.py", line 441, in _run_event
    await coro(*args, **kwargs)
  File "F:\Projetos\Yume²\yume.py", line 48, in on_ready
    yume_status.start()
  File "F:\Projetos\Yume²\.venv\Lib\site-packages\discord\ext\tasks\__init__.py", line 392, in start
    raise RuntimeError('Task is already launched and is not completed.')
RuntimeError: Task is already launched and is not completed.
2024-09-21 02:36:01,616: - discord.client - WARNING - PyNaCl is not installed, voice will NOT be supported
2024-09-21 02:36:01,857: - discord.client - INFO - logging in using static token
2024-09-21 02:36:03,151: - discord.gateway - INFO - Shard ID 0 has connected to Gateway (Session ID: baa17a935592c47ca663ed58d9856f14).
2024-09-21 02:36:05,172: - discord.client - ERROR - Ignoring exception in on_ready
Traceback (most recent call last):
  File "F:\Projetos\Yume²\.venv\Lib\site-packages\discord\client.py", line 441, in _run_event
    await coro(*args, **kwargs)
  File "F:\Projetos\Yume²\yume.py", line 48, in on_ready
    yume_status.start()
  File "F:\Projetos\Yume²\.venv\Lib\site-packages\discord\ext\tasks\__init__.py", line 392, in start
    raise RuntimeError('Task is already launched and is not completed.')
RuntimeError: Task is already launched and is not completed.
2024-09-21 02:45:49,719: - discord.client - WARNING - PyNaCl is not installed, voice will NOT be supported
2024-09-21 02:45:50,031: - discord.client - INFO - logging in using static token
2024-09-21 02:45:51,119: - discord.gateway - INFO - Shard ID 0 has connected to Gateway (Session ID: bb909f56e101bae6c0c3fb735fb41ca0).
2024-09-21 02:45:53,140: - discord.client - ERROR - Ignoring exception in on_ready
Traceback (most recent call last):
  File "F:\Projetos\Yume²\.venv\Lib\site-packages\discord\client.py", line 441, in _run_event
    await coro(*args, **kwargs)
  File "F:\Projetos\Yume²\yume.py", line 48, in on_ready
    yume_status.start()
  File "F:\Projetos\Yume²\.venv\Lib\site-packages\discord\ext\tasks\__init__.py", line 392, in start
    raise RuntimeError('Task is already launched and is not completed.')
RuntimeError: Task is already launched and is not completed.
2024-09-21 02:46:31,819: - discord.client - WARNING - PyNaCl is not installed, voice will NOT be supported
2024-09-21 02:46:32,038: - discord.client - INFO - logging in using static token
2024-09-21 02:46:33,158: - discord.gateway - INFO - Shard ID 0 has connected to Gateway (Session ID: 2633889a9b9f44017164d5a7b2e7e913).
2024-09-21 02:46:35,204: - discord.client - ERROR - Ignoring exception in on_ready
Traceback (most recent call last):
  File "F:\Projetos\Yume²\.venv\Lib\site-packages\discord\client.py", line 441, in _run_event
    await coro(*args, **kwargs)
  File "F:\Projetos\Yume²\yume.py", line 48, in on_ready
    yume_status.start()
  File "F:\Projetos\Yume²\.venv\Lib\site-packages\discord\ext\tasks\__init__.py", line 392, in start
    raise RuntimeError('Task is already launched and is not completed.')
RuntimeError: Task is already launched and is not completed.
2024-09-21 02:47:42,250: - discord.client - WARNING - PyNaCl is not installed, voice will NOT be supported
2024-09-21 02:47:42,481: - discord.client - INFO - logging in using static token
2024-09-21 02:47:44,833: - discord.gateway - INFO - Shard ID 0 has connected to Gateway (Session ID: 411c0ffb99425e41f04d7f76156d2cf5).
2024-09-21 02:47:46,861: - discord.client - ERROR - Ignoring exception in on_ready
Traceback (most recent call last):
  File "F:\Projetos\Yume²\.venv\Lib\site-packages\discord\client.py", line 441, in _run_event
    await coro(*args, **kwargs)
  File "F:\Projetos\Yume²\yume.py", line 48, in on_ready
    yume_status.start()
  File "F:\Projetos\Yume²\.venv\Lib\site-packages\discord\ext\tasks\__init__.py", line 392, in start
    raise RuntimeError('Task is already launched and is not completed.')
RuntimeError: Task is already launched and is not completed.
2024-09-21 02:47:54,817: - discord.app_commands.tree - ERROR - Ignoring exception in command 'typo'
Traceback (most recent call last):
  File "F:\Projetos\Yume²\.venv\Lib\site-packages\discord\app_commands\commands.py", line 827, in _do_call
    return await self._callback(self.binding, interaction, **params)  # type: ignore
           ^^^^^^^^^^^^^^^^^^^^^^^^^^^^^^^^^^^^^^^^^^^^^^^^^^^^^^^^^
  File "F:\Projetos\Yume²\cogs\dreams.py", line 37, in typo
    await interaction.response.send_modal(typo)
  File "F:\Projetos\Yume²\.venv\Lib\site-packages\discord\interactions.py", line 972, in send_modal
    await adapter.create_interaction_response(
  File "F:\Projetos\Yume²\.venv\Lib\site-packages\discord\webhook\async_.py", line 221, in request
    raise HTTPException(response, data)
discord.errors.HTTPException: 400 Bad Request (error code: 50035): Invalid Form Body
In data.components: Must be between 1 and 5 in length.

The above exception was the direct cause of the following exception:

Traceback (most recent call last):
  File "F:\Projetos\Yume²\.venv\Lib\site-packages\discord\app_commands\tree.py", line 1248, in _call
    await command._invoke_with_namespace(interaction, namespace)
  File "F:\Projetos\Yume²\.venv\Lib\site-packages\discord\app_commands\commands.py", line 853, in _invoke_with_namespace
    return await self._do_call(interaction, transformed_values)
           ^^^^^^^^^^^^^^^^^^^^^^^^^^^^^^^^^^^^^^^^^^^^^^^^^^^^
  File "F:\Projetos\Yume²\.venv\Lib\site-packages\discord\app_commands\commands.py", line 846, in _do_call
    raise CommandInvokeError(self, e) from e
discord.app_commands.errors.CommandInvokeError: Command 'typo' raised an exception: HTTPException: 400 Bad Request (error code: 50035): Invalid Form Body
In data.components: Must be between 1 and 5 in length.
2024-09-21 02:48:35,638: - discord.client - WARNING - PyNaCl is not installed, voice will NOT be supported
2024-09-21 02:48:35,922: - discord.client - INFO - logging in using static token
2024-09-21 02:48:37,043: - discord.gateway - INFO - Shard ID 0 has connected to Gateway (Session ID: 15cad719a48e1ddf95df11b109db372d).
2024-09-21 02:48:39,058: - discord.client - ERROR - Ignoring exception in on_ready
Traceback (most recent call last):
  File "F:\Projetos\Yume²\.venv\Lib\site-packages\discord\client.py", line 441, in _run_event
    await coro(*args, **kwargs)
  File "F:\Projetos\Yume²\yume.py", line 48, in on_ready
    yume_status.start()
  File "F:\Projetos\Yume²\.venv\Lib\site-packages\discord\ext\tasks\__init__.py", line 392, in start
    raise RuntimeError('Task is already launched and is not completed.')
RuntimeError: Task is already launched and is not completed.
2024-09-21 02:48:54,963: - discord.client - WARNING - PyNaCl is not installed, voice will NOT be supported
2024-09-21 02:48:55,203: - discord.client - INFO - logging in using static token
2024-09-21 02:48:57,531: - discord.gateway - INFO - Shard ID 0 has connected to Gateway (Session ID: a32b307154250cf2134e11439338a986).
2024-09-21 02:48:59,586: - discord.client - ERROR - Ignoring exception in on_ready
Traceback (most recent call last):
  File "F:\Projetos\Yume²\.venv\Lib\site-packages\discord\client.py", line 441, in _run_event
    await coro(*args, **kwargs)
  File "F:\Projetos\Yume²\yume.py", line 48, in on_ready
    yume_status.start()
  File "F:\Projetos\Yume²\.venv\Lib\site-packages\discord\ext\tasks\__init__.py", line 392, in start
    raise RuntimeError('Task is already launched and is not completed.')
RuntimeError: Task is already launched and is not completed.
2024-09-21 02:49:03,727: - discord.app_commands.tree - ERROR - Ignoring exception in command 'typo'
Traceback (most recent call last):
  File "F:\Projetos\Yume²\.venv\Lib\site-packages\discord\app_commands\commands.py", line 827, in _do_call
    return await self._callback(self.binding, interaction, **params)  # type: ignore
           ^^^^^^^^^^^^^^^^^^^^^^^^^^^^^^^^^^^^^^^^^^^^^^^^^^^^^^^^^
  File "F:\Projetos\Yume²\cogs\dreams.py", line 37, in typo
    await interaction.response.send_modal(typo)
  File "F:\Projetos\Yume²\.venv\Lib\site-packages\discord\interactions.py", line 972, in send_modal
    await adapter.create_interaction_response(
  File "F:\Projetos\Yume²\.venv\Lib\site-packages\discord\webhook\async_.py", line 221, in request
    raise HTTPException(response, data)
discord.errors.HTTPException: 400 Bad Request (error code: 50035): Invalid Form Body
In data.components: Must be between 1 and 5 in length.

The above exception was the direct cause of the following exception:

Traceback (most recent call last):
  File "F:\Projetos\Yume²\.venv\Lib\site-packages\discord\app_commands\tree.py", line 1248, in _call
    await command._invoke_with_namespace(interaction, namespace)
  File "F:\Projetos\Yume²\.venv\Lib\site-packages\discord\app_commands\commands.py", line 853, in _invoke_with_namespace
    return await self._do_call(interaction, transformed_values)
           ^^^^^^^^^^^^^^^^^^^^^^^^^^^^^^^^^^^^^^^^^^^^^^^^^^^^
  File "F:\Projetos\Yume²\.venv\Lib\site-packages\discord\app_commands\commands.py", line 846, in _do_call
    raise CommandInvokeError(self, e) from e
discord.app_commands.errors.CommandInvokeError: Command 'typo' raised an exception: HTTPException: 400 Bad Request (error code: 50035): Invalid Form Body
In data.components: Must be between 1 and 5 in length.
2024-09-21 02:50:14,312: - discord.client - WARNING - PyNaCl is not installed, voice will NOT be supported
2024-09-21 02:50:14,569: - discord.client - INFO - logging in using static token
2024-09-21 02:50:15,780: - discord.gateway - INFO - Shard ID 0 has connected to Gateway (Session ID: 78a8a7fbfcc8588cb56a89ae6617e8cf).
2024-09-21 02:50:17,851: - discord.client - ERROR - Ignoring exception in on_ready
Traceback (most recent call last):
  File "F:\Projetos\Yume²\.venv\Lib\site-packages\discord\client.py", line 441, in _run_event
    await coro(*args, **kwargs)
  File "F:\Projetos\Yume²\yume.py", line 48, in on_ready
    yume_status.start()
  File "F:\Projetos\Yume²\.venv\Lib\site-packages\discord\ext\tasks\__init__.py", line 392, in start
    raise RuntimeError('Task is already launched and is not completed.')
RuntimeError: Task is already launched and is not completed.
2024-09-21 02:50:37,198: - discord.client - WARNING - PyNaCl is not installed, voice will NOT be supported
2024-09-21 02:50:37,431: - discord.client - INFO - logging in using static token
2024-09-21 02:50:38,447: - discord.gateway - INFO - Shard ID 0 has connected to Gateway (Session ID: fb817828013ef217bdc9ecea9814d7a7).
2024-09-21 02:50:40,480: - discord.client - ERROR - Ignoring exception in on_ready
Traceback (most recent call last):
  File "F:\Projetos\Yume²\.venv\Lib\site-packages\discord\client.py", line 441, in _run_event
    await coro(*args, **kwargs)
  File "F:\Projetos\Yume²\yume.py", line 48, in on_ready
    yume_status.start()
  File "F:\Projetos\Yume²\.venv\Lib\site-packages\discord\ext\tasks\__init__.py", line 392, in start
    raise RuntimeError('Task is already launched and is not completed.')
RuntimeError: Task is already launched and is not completed.
2024-09-21 02:51:36,831: - discord.client - WARNING - PyNaCl is not installed, voice will NOT be supported
2024-09-21 02:51:37,054: - discord.client - INFO - logging in using static token
2024-09-21 02:51:38,141: - discord.gateway - INFO - Shard ID 0 has connected to Gateway (Session ID: 727d47adc6b51af5e12ea7d31a945937).
2024-09-21 02:51:40,151: - discord.client - ERROR - Ignoring exception in on_ready
Traceback (most recent call last):
  File "F:\Projetos\Yume²\.venv\Lib\site-packages\discord\client.py", line 441, in _run_event
    await coro(*args, **kwargs)
  File "F:\Projetos\Yume²\yume.py", line 48, in on_ready
    yume_status.start()
  File "F:\Projetos\Yume²\.venv\Lib\site-packages\discord\ext\tasks\__init__.py", line 392, in start
    raise RuntimeError('Task is already launched and is not completed.')
RuntimeError: Task is already launched and is not completed.
2024-09-21 02:52:23,451: - discord.client - WARNING - PyNaCl is not installed, voice will NOT be supported
2024-09-21 02:52:23,698: - discord.client - INFO - logging in using static token
2024-09-21 02:52:26,155: - discord.gateway - INFO - Shard ID 0 has connected to Gateway (Session ID: d49710bb159bbaffefa37262aa57f170).
2024-09-21 02:52:28,172: - discord.client - ERROR - Ignoring exception in on_ready
Traceback (most recent call last):
  File "F:\Projetos\Yume²\.venv\Lib\site-packages\discord\client.py", line 441, in _run_event
    await coro(*args, **kwargs)
  File "F:\Projetos\Yume²\yume.py", line 48, in on_ready
    yume_status.start()
  File "F:\Projetos\Yume²\.venv\Lib\site-packages\discord\ext\tasks\__init__.py", line 392, in start
    raise RuntimeError('Task is already launched and is not completed.')
RuntimeError: Task is already launched and is not completed.
2024-09-21 02:52:48,628: - discord.client - WARNING - PyNaCl is not installed, voice will NOT be supported
2024-09-21 02:52:48,873: - discord.client - INFO - logging in using static token
2024-09-21 02:52:50,016: - discord.gateway - INFO - Shard ID 0 has connected to Gateway (Session ID: 9498096b60b0469b3da3eae21dd24b14).
2024-09-21 02:52:52,025: - discord.client - ERROR - Ignoring exception in on_ready
Traceback (most recent call last):
  File "F:\Projetos\Yume²\.venv\Lib\site-packages\discord\client.py", line 441, in _run_event
    await coro(*args, **kwargs)
  File "F:\Projetos\Yume²\yume.py", line 48, in on_ready
    yume_status.start()
  File "F:\Projetos\Yume²\.venv\Lib\site-packages\discord\ext\tasks\__init__.py", line 392, in start
    raise RuntimeError('Task is already launched and is not completed.')
RuntimeError: Task is already launched and is not completed.
2024-09-21 03:05:50,366: - discord.client - WARNING - PyNaCl is not installed, voice will NOT be supported
2024-09-21 03:05:50,670: - discord.client - INFO - logging in using static token
2024-09-21 03:05:51,915: - discord.gateway - INFO - Shard ID 0 has connected to Gateway (Session ID: a3d5c894af3aa239fea81736d1afb223).
2024-09-21 03:05:53,967: - discord.client - ERROR - Ignoring exception in on_ready
Traceback (most recent call last):
  File "F:\Projetos\Yume²\.venv\Lib\site-packages\discord\client.py", line 441, in _run_event
    await coro(*args, **kwargs)
  File "F:\Projetos\Yume²\yume.py", line 48, in on_ready
    yume_status.start()
  File "F:\Projetos\Yume²\.venv\Lib\site-packages\discord\ext\tasks\__init__.py", line 392, in start
    raise RuntimeError('Task is already launched and is not completed.')
RuntimeError: Task is already launched and is not completed.
2024-09-21 03:32:40,044: - discord.client - WARNING - PyNaCl is not installed, voice will NOT be supported
2024-09-21 03:33:11,832: - discord.client - WARNING - PyNaCl is not installed, voice will NOT be supported
2024-09-21 03:33:11,842: - discord.client - INFO - logging in using static token
2024-09-21 03:33:12,990: - discord.gateway - INFO - Shard ID 0 has connected to Gateway (Session ID: 8542919764710c802e5f7c4dc57e7a67).
2024-09-21 03:33:15,010: - discord.client - ERROR - Ignoring exception in on_ready
Traceback (most recent call last):
  File "F:\Projetos\Yume²\.venv\Lib\site-packages\discord\client.py", line 441, in _run_event
    await coro(*args, **kwargs)
  File "F:\Projetos\Yume²\yume.py", line 47, in on_ready
    yume_status.start()
  File "F:\Projetos\Yume²\.venv\Lib\site-packages\discord\ext\tasks\__init__.py", line 392, in start
    raise RuntimeError('Task is already launched and is not completed.')
RuntimeError: Task is already launched and is not completed.
2024-09-21 03:34:12,160: - discord.client - WARNING - PyNaCl is not installed, voice will NOT be supported
2024-09-21 03:34:12,172: - discord.client - INFO - logging in using static token
2024-09-21 03:34:14,347: - discord.gateway - INFO - Shard ID 0 has connected to Gateway (Session ID: 5383a283aa304617b460ac23877287b5).
2024-09-21 03:34:16,481: - discord.client - ERROR - Ignoring exception in on_ready
Traceback (most recent call last):
  File "F:\Projetos\Yume²\.venv\Lib\site-packages\discord\client.py", line 441, in _run_event
    await coro(*args, **kwargs)
  File "F:\Projetos\Yume²\yume.py", line 47, in on_ready
    yume_status.start()
  File "F:\Projetos\Yume²\.venv\Lib\site-packages\discord\ext\tasks\__init__.py", line 392, in start
    raise RuntimeError('Task is already launched and is not completed.')
RuntimeError: Task is already launched and is not completed.
2024-09-21 03:35:27,024: - discord.client - WARNING - PyNaCl is not installed, voice will NOT be supported
2024-09-21 03:35:27,035: - discord.client - INFO - logging in using static token
2024-09-21 03:35:28,098: - discord.gateway - INFO - Shard ID 0 has connected to Gateway (Session ID: fbaf02de9fed5e625dec35c6404007d2).
2024-09-21 03:35:30,138: - discord.client - ERROR - Ignoring exception in on_ready
Traceback (most recent call last):
  File "F:\Projetos\Yume²\.venv\Lib\site-packages\discord\client.py", line 441, in _run_event
    await coro(*args, **kwargs)
  File "F:\Projetos\Yume²\yume.py", line 47, in on_ready
    yume_status.start()
  File "F:\Projetos\Yume²\.venv\Lib\site-packages\discord\ext\tasks\__init__.py", line 392, in start
    raise RuntimeError('Task is already launched and is not completed.')
RuntimeError: Task is already launched and is not completed.
2024-09-21 03:36:25,715: - discord.client - WARNING - PyNaCl is not installed, voice will NOT be supported
2024-09-21 03:36:25,729: - discord.client - INFO - logging in using static token
2024-09-21 03:36:26,797: - discord.gateway - INFO - Shard ID 0 has connected to Gateway (Session ID: a174b734f25d3cd88b37be3d196b9f1b).
2024-09-21 03:36:28,843: - discord.client - ERROR - Ignoring exception in on_ready
Traceback (most recent call last):
  File "F:\Projetos\Yume²\.venv\Lib\site-packages\discord\client.py", line 441, in _run_event
    await coro(*args, **kwargs)
  File "F:\Projetos\Yume²\yume.py", line 47, in on_ready
    yume_status.start()
  File "F:\Projetos\Yume²\.venv\Lib\site-packages\discord\ext\tasks\__init__.py", line 392, in start
    raise RuntimeError('Task is already launched and is not completed.')
RuntimeError: Task is already launched and is not completed.
2024-09-21 03:44:42,546: - discord.client - WARNING - PyNaCl is not installed, voice will NOT be supported
2024-09-21 03:44:42,558: - discord.client - INFO - logging in using static token
2024-09-21 03:44:43,636: - discord.gateway - INFO - Shard ID 0 has connected to Gateway (Session ID: a37122ac603caf7adfe856c3aed4aa14).
2024-09-21 03:44:45,656: - discord.client - ERROR - Ignoring exception in on_ready
Traceback (most recent call last):
  File "F:\Projetos\Yume²\.venv\Lib\site-packages\discord\client.py", line 441, in _run_event
    await coro(*args, **kwargs)
  File "F:\Projetos\Yume²\yume.py", line 47, in on_ready
    yume_status.start()
  File "F:\Projetos\Yume²\.venv\Lib\site-packages\discord\ext\tasks\__init__.py", line 392, in start
    raise RuntimeError('Task is already launched and is not completed.')
RuntimeError: Task is already launched and is not completed.
2024-09-21 03:45:45,664: - discord.client - WARNING - PyNaCl is not installed, voice will NOT be supported
2024-09-21 03:45:45,675: - discord.client - INFO - logging in using static token
2024-09-21 03:45:46,835: - discord.gateway - INFO - Shard ID 0 has connected to Gateway (Session ID: 82c4978e1e02424960b463f30c09f818).
2024-09-21 03:45:48,867: - discord.client - ERROR - Ignoring exception in on_ready
Traceback (most recent call last):
  File "F:\Projetos\Yume²\.venv\Lib\site-packages\discord\client.py", line 441, in _run_event
    await coro(*args, **kwargs)
  File "F:\Projetos\Yume²\yume.py", line 47, in on_ready
    yume_status.start()
  File "F:\Projetos\Yume²\.venv\Lib\site-packages\discord\ext\tasks\__init__.py", line 392, in start
    raise RuntimeError('Task is already launched and is not completed.')
RuntimeError: Task is already launched and is not completed.
2024-09-21 03:46:59,036: - discord.client - WARNING - PyNaCl is not installed, voice will NOT be supported
2024-09-21 03:46:59,047: - discord.client - INFO - logging in using static token
2024-09-21 03:47:00,177: - discord.gateway - INFO - Shard ID 0 has connected to Gateway (Session ID: a1bf91f021520d7e048dce11b623b1cd).
2024-09-21 03:47:02,230: - discord.client - ERROR - Ignoring exception in on_ready
Traceback (most recent call last):
  File "F:\Projetos\Yume²\.venv\Lib\site-packages\discord\client.py", line 441, in _run_event
    await coro(*args, **kwargs)
  File "F:\Projetos\Yume²\yume.py", line 47, in on_ready
    yume_status.start()
  File "F:\Projetos\Yume²\.venv\Lib\site-packages\discord\ext\tasks\__init__.py", line 392, in start
    raise RuntimeError('Task is already launched and is not completed.')
RuntimeError: Task is already launched and is not completed.
2024-09-21 03:47:28,812: - discord.client - WARNING - PyNaCl is not installed, voice will NOT be supported
2024-09-21 03:47:28,824: - discord.client - INFO - logging in using static token
2024-09-21 03:47:29,852: - discord.gateway - INFO - Shard ID 0 has connected to Gateway (Session ID: 8687721628bf4c4c7f05382f623821a4).
2024-09-21 03:47:31,906: - discord.client - ERROR - Ignoring exception in on_ready
Traceback (most recent call last):
  File "F:\Projetos\Yume²\.venv\Lib\site-packages\discord\client.py", line 441, in _run_event
    await coro(*args, **kwargs)
  File "F:\Projetos\Yume²\yume.py", line 47, in on_ready
    yume_status.start()
  File "F:\Projetos\Yume²\.venv\Lib\site-packages\discord\ext\tasks\__init__.py", line 392, in start
    raise RuntimeError('Task is already launched and is not completed.')
RuntimeError: Task is already launched and is not completed.
2024-09-21 03:49:34,879: - discord.client - WARNING - PyNaCl is not installed, voice will NOT be supported
2024-09-21 03:49:34,890: - discord.client - INFO - logging in using static token
2024-09-21 03:49:35,967: - discord.gateway - INFO - Shard ID 0 has connected to Gateway (Session ID: d6cea64b0570f35b954ad2daab34f1ce).
2024-09-21 03:49:37,996: - discord.client - ERROR - Ignoring exception in on_ready
Traceback (most recent call last):
  File "F:\Projetos\Yume²\.venv\Lib\site-packages\discord\client.py", line 441, in _run_event
    await coro(*args, **kwargs)
  File "F:\Projetos\Yume²\yume.py", line 47, in on_ready
    yume_status.start()
  File "F:\Projetos\Yume²\.venv\Lib\site-packages\discord\ext\tasks\__init__.py", line 392, in start
    raise RuntimeError('Task is already launched and is not completed.')
RuntimeError: Task is already launched and is not completed.
2024-09-21 03:52:23,874: - discord.client - WARNING - PyNaCl is not installed, voice will NOT be supported
2024-09-21 03:52:23,886: - discord.client - INFO - logging in using static token
2024-09-21 03:52:25,078: - discord.gateway - INFO - Shard ID 0 has connected to Gateway (Session ID: 77ca0562a21c13539e0ff152e2f05f28).
2024-09-21 03:53:19,902: - discord.client - WARNING - PyNaCl is not installed, voice will NOT be supported
2024-09-21 03:53:19,912: - discord.client - INFO - logging in using static token
2024-09-21 03:53:21,139: - discord.gateway - INFO - Shard ID 0 has connected to Gateway (Session ID: 4d754fe00626ae0cd8cfa6164d0eccf6).
2024-09-21 03:53:23,167: - discord.client - ERROR - Ignoring exception in on_ready
Traceback (most recent call last):
  File "F:\Projetos\Yume²\.venv\Lib\site-packages\discord\client.py", line 441, in _run_event
    await coro(*args, **kwargs)
  File "F:\Projetos\Yume²\yume.py", line 47, in on_ready
    yume_status.start()
  File "F:\Projetos\Yume²\.venv\Lib\site-packages\discord\ext\tasks\__init__.py", line 392, in start
    raise RuntimeError('Task is already launched and is not completed.')
RuntimeError: Task is already launched and is not completed.
2024-09-21 03:56:24,024: - discord.client - WARNING - PyNaCl is not installed, voice will NOT be supported
2024-09-21 03:56:24,036: - discord.client - INFO - logging in using static token
2024-09-21 03:56:25,341: - discord.gateway - INFO - Shard ID 0 has connected to Gateway (Session ID: 92947bc636074eef33ecfd07b5dda110).
2024-09-21 03:56:27,364: - discord.client - ERROR - Ignoring exception in on_ready
Traceback (most recent call last):
  File "F:\Projetos\Yume²\.venv\Lib\site-packages\discord\client.py", line 441, in _run_event
    await coro(*args, **kwargs)
  File "F:\Projetos\Yume²\yume.py", line 47, in on_ready
    yume_status.start()
  File "F:\Projetos\Yume²\.venv\Lib\site-packages\discord\ext\tasks\__init__.py", line 392, in start
    raise RuntimeError('Task is already launched and is not completed.')
RuntimeError: Task is already launched and is not completed.
2024-09-21 04:00:13,659: - discord.client - WARNING - PyNaCl is not installed, voice will NOT be supported
2024-09-21 04:00:13,670: - discord.client - INFO - logging in using static token
2024-09-21 04:00:15,190: - discord.gateway - INFO - Shard ID 0 has connected to Gateway (Session ID: 8e0408cb49186d461eb6dc6bbb57075a).
2024-09-21 04:00:17,199: - discord.client - ERROR - Ignoring exception in on_ready
Traceback (most recent call last):
  File "F:\Projetos\Yume²\.venv\Lib\site-packages\discord\client.py", line 441, in _run_event
    await coro(*args, **kwargs)
  File "F:\Projetos\Yume²\yume.py", line 47, in on_ready
    yume_status.start()
  File "F:\Projetos\Yume²\.venv\Lib\site-packages\discord\ext\tasks\__init__.py", line 392, in start
    raise RuntimeError('Task is already launched and is not completed.')
RuntimeError: Task is already launched and is not completed.
2024-09-21 04:00:56,791: - discord.client - WARNING - PyNaCl is not installed, voice will NOT be supported
2024-09-21 04:00:56,802: - discord.client - INFO - logging in using static token
2024-09-21 04:00:58,038: - discord.gateway - INFO - Shard ID 0 has connected to Gateway (Session ID: 0c23ecc6305f5859802a804a3c40904a).
2024-09-21 04:01:00,090: - discord.client - ERROR - Ignoring exception in on_ready
Traceback (most recent call last):
  File "F:\Projetos\Yume²\.venv\Lib\site-packages\discord\client.py", line 441, in _run_event
    await coro(*args, **kwargs)
  File "F:\Projetos\Yume²\yume.py", line 47, in on_ready
    yume_status.start()
  File "F:\Projetos\Yume²\.venv\Lib\site-packages\discord\ext\tasks\__init__.py", line 392, in start
    raise RuntimeError('Task is already launched and is not completed.')
RuntimeError: Task is already launched and is not completed.
2024-09-21 04:01:41,522: - discord.client - WARNING - PyNaCl is not installed, voice will NOT be supported
2024-09-21 04:01:41,533: - discord.client - INFO - logging in using static token
2024-09-21 04:01:42,523: - discord.gateway - INFO - Shard ID 0 has connected to Gateway (Session ID: 8252260bdfab86574a10b780ca71b71a).
2024-09-21 04:01:44,548: - discord.client - ERROR - Ignoring exception in on_ready
Traceback (most recent call last):
  File "F:\Projetos\Yume²\.venv\Lib\site-packages\discord\client.py", line 441, in _run_event
    await coro(*args, **kwargs)
  File "F:\Projetos\Yume²\yume.py", line 47, in on_ready
    yume_status.start()
  File "F:\Projetos\Yume²\.venv\Lib\site-packages\discord\ext\tasks\__init__.py", line 392, in start
    raise RuntimeError('Task is already launched and is not completed.')
RuntimeError: Task is already launched and is not completed.
2024-09-21 04:03:06,580: - discord.client - WARNING - PyNaCl is not installed, voice will NOT be supported
2024-09-21 04:03:06,592: - discord.client - INFO - logging in using static token
2024-09-21 04:03:07,751: - discord.gateway - INFO - Shard ID 0 has connected to Gateway (Session ID: 9a387136415bdcc54492626f887f0d3e).
2024-09-21 04:03:09,791: - discord.client - ERROR - Ignoring exception in on_ready
Traceback (most recent call last):
  File "F:\Projetos\Yume²\.venv\Lib\site-packages\discord\client.py", line 441, in _run_event
    await coro(*args, **kwargs)
  File "F:\Projetos\Yume²\yume.py", line 47, in on_ready
    yume_status.start()
  File "F:\Projetos\Yume²\.venv\Lib\site-packages\discord\ext\tasks\__init__.py", line 392, in start
    raise RuntimeError('Task is already launched and is not completed.')
RuntimeError: Task is already launched and is not completed.
